<?xml version="1.0"?>

<robot xmlns:xacro="http://ros.org/wiki/xacro" name="robot_essentials">

  <!--######################################################################-->
  <xacro:macro name="robot_wheel" params="prefix">

    <link name="${prefix}_wheel">
      <inertial>
        <origin xyz="0 0 0" rpy="0 0 0" />
        <mass value="0.30" />
        <inertia ixx="0.01" ixy="0.0" ixz="0.0" iyy="0.01" iyz="0.0" izz="0.01" />
      </inertial>
      <visual>
        <origin xyz="0 0 0" rpy="0 0 0" />
        <geometry>
          <mesh filename="package://robot_description/meshes/wheel.stl" scale="0.001 0.001 0.001" />
        </geometry>
        <material name="">
          <color rgba="0.79216 0.81961 0.93333 1" />
        </material>
      </visual>
      <collision>
        <origin xyz="0 0 0" rpy="0 0 0" />
        <geometry>
          <mesh filename="package://robot_description/meshes/wheel.stl" scale="0.001 0.001 0.001" />
        </geometry>
      </collision>
    </link>

  </xacro:macro>

  <!--######################################################################-->
  <xacro:macro name="robot_sphere" params="prefix">

    <link name="${prefix}_sphere">
      <inertial>
        <origin xyz="0 0 0" rpy="0 0 0" />
        <mass value="0.2" />
        <inertia ixx="0.01" ixy="0" ixz="0" iyy="0.01" iyz="0" izz="0.01" />
      </inertial>
      <visual>
        <origin xyz="0 0 0" rpy="0 0 0" />
        <geometry>
          <mesh filename="package://robot_description/meshes/sphere.stl" scale="0.001 0.001 0.001" />
        </geometry>
        <material name="">
          <color rgba="0.79216 0.81961 0.93333 1" />
        </material>
      </visual>
      <collision>
        <origin xyz="0 0 0" rpy="0 0 0" />
        <geometry>
          <mesh filename="package://robot_description/meshes/sphere.stl" scale="0.001 0.001 0.001" />
        </geometry>
      </collision>
    </link>

  </xacro:macro>


  <!--######################################################################-->
  <xacro:macro name="sphere_joint" params="prefix origin">

    <joint name="${prefix}_sphere_joint" type="fixed">
      <axis xyz="1 1 1" />
      <parent link="base_link" />
      <child link="${prefix}_sphere" />
      <origin rpy="0 0 0" xyz="${origin}" />
    </joint>

  </xacro:macro>

  <!--######################################################################-->
  <xacro:macro name="wheel_joint" params="prefix origin">

    <joint name="${prefix}_wheel_joint" type="continuous">
      <axis xyz="0 1 0" />
      <parent link="base_link" />
      <child link="${prefix}_wheel" />
      <origin rpy="0 0 0" xyz="${origin}" />
    </joint>

  </xacro:macro>


  <!--######################################################################-->
  <xacro:macro name="base_transmission" params="prefix ">

    <transmission name="${prefix}_wheel_trans" type="SimpleTransmission">
      <type>transmission_interface/SimpleTransmission</type>
      <actuator name="${prefix}_wheel_motor">
        <hardwareInterface>hardware_interface/VelocityJointInterface</hardwareInterface>
        <mechanicalReduction>1</mechanicalReduction>
      </actuator>
      <joint name="${prefix}_wheel_joint">
        <hardwareInterface>hardware_interface/VelocityJointInterface</hardwareInterface>
      </joint>
    </transmission>

  </xacro:macro>

  <!--######################################################################-->
  <link name="laser_link">
    <collision>
      <origin xyz="0 0 0" rpy="0 0 0" />
      <geometry>
        <box size="0.1 0.1 0.05" />
      </geometry>
    </collision>
    <visual>
      <origin xyz="0 0 0" rpy="0 0 0" />
      <geometry>
        <box size="0.05 0.05 0.05" />
      </geometry>
    </visual>
    <inertial>
      <mass value="1e-5" />
      <origin xyz="0 0 0" rpy="0 0 0" />
      <inertia ixx="1e-6" ixy="0" ixz="0" iyy="1e-6" iyz="0" izz="1e-6" />
    </inertial>
  </link>

  <joint name="laser_joint" type="fixed">
    <axis xyz="0 1 0" />
    <origin xyz="-0.15 0 0.2" rpy="0 0 0" />
    <parent link="base_link" />
    <child link="laser_link" />
  </joint>


  <!--######################################################################-->
  <link name="imu_link" />

  <joint name="imu_joint" type="fixed">
    <parent link="base_link" />
    <child link="imu_link" />
    <origin xyz="0.0 0 0.07" rpy="0 0 0" />
  </joint>

</robot>